Workbook

Sheet Dataset
A2: 01 Dataset
A4: Dog-Wolf (10 objects, 6 quantitative features, 2 classes) | J4: Experiment settings
A5: Object | B5: x1 | C5: x2 | D5: x3 | E5: x4 | F5: x5 | G5: x6 | H5: Class | J5: Setting | K5: Value
A6: S1 | B6: 129 | C6: 64 | D6: 95 | E6: 17.5 | F6: 11.2 | G6: 13.8 | H6: 1 | J6: Objects | K6: =COUNT(H6:H15) -> 10
A7: S2 | B7: 154 | C7: 74 | D7: 76 | E7: 20 | F7: 14.2 | G7: 16.5 | H7: 1 | J7: Features | K7: 6
A8: S3 | B8: 199 | C8: 105 | D8: 73 | E8: 23.4 | F8: 15 | G8: 19.1 | H8: 2 | J8: Class K1 | K8: =COUNTIFS(H6:H15,1) -> 6
A9: S4 | B9: 170 | C9: 87 | D9: 71 | E9: 17.9 | F9: 12.3 | G9: 15.9 | H9: 1 | J9: Class K2 | K9: =COUNTIFS(H6:H15,2) -> 4
A10: S5 | B10: 227 | C10: 117 | D10: 77 | E10: 25 | F10: 15.3 | G10: 18.6 | H10: 2 | J10: k max | K10: =MIN(K6-1,2*MIN(K8,K9)-3) -> 5
A11: S6 | B11: 188 | C11: 94 | D11: 73 | E11: 19.5 | F11: 13.3 | G11: 14.8 | H11: 1 | J11: Full k | K11: 1, 2, 3, 4, 5
A12: S7 | B12: 161 | C12: 81 | D12: 55 | E12: 17.1 | F12: 12.1 | G12: 13 | H12: 1 | J12: Reduced k | K12: 3, 5
A13: S8 | B13: 164 | C13: 90 | D13: 58 | E13: 17.5 | F13: 12.7 | G13: 14.7 | H13: 1 | J13: Normalization | K13: None and MinMax
A14: S9 | B14: 228 | C14: 122 | D14: 82 | E14: 24.7 | F14: 15 | G14: 18.5 | H14: 2
A15: S10 | B15: 232 | C15: 123 | D15: 83 | E15: 25.3 | F15: 16.8 | G15: 15.5 | H15: 2
A18: Min-max normalized dataset
A19: Object | B19: x1 | C19: x2 | D19: x3 | E19: x4 | F19: x5 | G19: x6 | H19: Class
A20: S1 | B20: =IF(MAX(B$6:B$15)=MIN(B$6:B$15),0,(B6-MIN(B$6:B$15))/(MAX(B$6:B$15)-MIN(B$6:B$15))) -> 0 | C20: =IF(MAX(C$6:C$15)=MIN(C$6:C$15),0,(C6-MIN(C$6:C$15))/(MAX(C$6:C$15)-MIN(C$6:C$15))) -> 0 | D20: =IF(MAX(D$6:D$15)=MIN(D$6:D$15),0,(D6-MIN(D$6:D$15))/(MAX(D$6:D$15)-MIN(D$6:D$15))) -> 1 | E20: =IF(MAX(E$6:E$15)=MIN(E$6:E$15),0,(E6-MIN(E$6:E$15))/(MAX(E$6:E$15)-MIN(E$6:E$15))) -> 0.048780488 | F20: =IF(MAX(F$6:F$15)=MIN(F$6:F$15),0,(F6-MIN(F$6:F$15))/(MAX(F$6:F$15)-MIN(F$6:F$15))) -> 0 | G20: =IF(MAX(G$6:G$15)=MIN(G$6:G$15),0,(G6-MIN(G$6:G$15))/(MAX(G$6:G$15)-MIN(G$6:G$15))) -> 0.13114754 | H20: 1
A21: S2 | B21: =IF(MAX(B$6:B$15)=MIN(B$6:B$15),0,(B7-MIN(B$6:B$15))/(MAX(B$6:B$15)-MIN(B$6:B$15))) -> 0.24271845 | C21: =IF(MAX(C$6:C$15)=MIN(C$6:C$15),0,(C7-MIN(C$6:C$15))/(MAX(C$6:C$15)-MIN(C$6:C$15))) -> 0.16949153 | D21: =IF(MAX(D$6:D$15)=MIN(D$6:D$15),0,(D7-MIN(D$6:D$15))/(MAX(D$6:D$15)-MIN(D$6:D$15))) -> 0.525 | E21: =IF(MAX(E$6:E$15)=MIN(E$6:E$15),0,(E7-MIN(E$6:E$15))/(MAX(E$6:E$15)-MIN(E$6:E$15))) -> 0.35365854 | F21: =IF(MAX(F$6:F$15)=MIN(F$6:F$15),0,(F7-MIN(F$6:F$15))/(MAX(F$6:F$15)-MIN(F$6:F$15))) -> 0.53571429 | G21: =IF(MAX(G$6:G$15)=MIN(G$6:G$15),0,(G7-MIN(G$6:G$15))/(MAX(G$6:G$15)-MIN(G$6:G$15))) -> 0.57377049 | H21: 1
A22: S3 | B22: =IF(MAX(B$6:B$15)=MIN(B$6:B$15),0,(B8-MIN(B$6:B$15))/(MAX(B$6:B$15)-MIN(B$6:B$15))) -> 0.67961165 | C22: =IF(MAX(C$6:C$15)=MIN(C$6:C$15),0,(C8-MIN(C$6:C$15))/(MAX(C$6:C$15)-MIN(C$6:C$15))) -> 0.69491525 | D22: =IF(MAX(D$6:D$15)=MIN(D$6:D$15),0,(D8-MIN(D$6:D$15))/(MAX(D$6:D$15)-MIN(D$6:D$15))) -> 0.45 | E22: =IF(MAX(E$6:E$15)=MIN(E$6:E$15),0,(E8-MIN(E$6:E$15))/(MAX(E$6:E$15)-MIN(E$6:E$15))) -> 0.76829268 | F22: =IF(MAX(F$6:F$15)=MIN(F$6:F$15),0,(F8-MIN(F$6:F$15))/(MAX(F$6:F$15)-MIN(F$6:F$15))) -> 0.67857143 | G22: =IF(MAX(G$6:G$15)=MIN(G$6:G$15),0,(G8-MIN(G$6:G$15))/(MAX(G$6:G$15)-MIN(G$6:G$15))) -> 1 | H22: 2
A23: S4 | B23: =IF(MAX(B$6:B$15)=MIN(B$6:B$15),0,(B9-MIN(B$6:B$15))/(MAX(B$6:B$15)-MIN(B$6:B$15))) -> 0.39805825 | C23: =IF(MAX(C$6:C$15)=MIN(C$6:C$15),0,(C9-MIN(C$6:C$15))/(MAX(C$6:C$15)-MIN(C$6:C$15))) -> 0.38983051 | D23: =IF(MAX(D$6:D$15)=MIN(D$6:D$15),0,(D9-MIN(D$6:D$15))/(MAX(D$6:D$15)-MIN(D$6:D$15))) -> 0.4 | E23: =IF(MAX(E$6:E$15)=MIN(E$6:E$15),0,(E9-MIN(E$6:E$15))/(MAX(E$6:E$15)-MIN(E$6:E$15))) -> 0.097560976 | F23: =IF(MAX(F$6:F$15)=MIN(F$6:F$15),0,(F9-MIN(F$6:F$15))/(MAX(F$6:F$15)-MIN(F$6:F$15))) -> 0.19642857 | G23: =IF(MAX(G$6:G$15)=MIN(G$6:G$15),0,(G9-MIN(G$6:G$15))/(MAX(G$6:G$15)-MIN(G$6:G$15))) -> 0.47540984 | H23: 1
A24: S5 | B24: =IF(MAX(B$6:B$15)=MIN(B$6:B$15),0,(B10-MIN(B$6:B$15))/(MAX(B$6:B$15)-MIN(B$6:B$15))) -> 0.95145631 | C24: =IF(MAX(C$6:C$15)=MIN(C$6:C$15),0,(C10-MIN(C$6:C$15))/(MAX(C$6:C$15)-MIN(C$6:C$15))) -> 0.89830508 | D24: =IF(MAX(D$6:D$15)=MIN(D$6:D$15),0,(D10-MIN(D$6:D$15))/(MAX(D$6:D$15)-MIN(D$6:D$15))) -> 0.55 | E24: =IF(MAX(E$6:E$15)=MIN(E$6:E$15),0,(E10-MIN(E$6:E$15))/(MAX(E$6:E$15)-MIN(E$6:E$15))) -> 0.96341463 | F24: =IF(MAX(F$6:F$15)=MIN(F$6:F$15),0,(F10-MIN(F$6:F$15))/(MAX(F$6:F$15)-MIN(F$6:F$15))) -> 0.73214286 | G24: =IF(MAX(G$6:G$15)=MIN(G$6:G$15),0,(G10-MIN(G$6:G$15))/(MAX(G$6:G$15)-MIN(G$6:G$15))) -> 0.91803279 | H24: 2
A25: S6 | B25: =IF(MAX(B$6:B$15)=MIN(B$6:B$15),0,(B11-MIN(B$6:B$15))/(MAX(B$6:B$15)-MIN(B$6:B$15))) -> 0.57281553 | C25: =IF(MAX(C$6:C$15)=MIN(C$6:C$15),0,(C11-MIN(C$6:C$15))/(MAX(C$6:C$15)-MIN(C$6:C$15))) -> 0.50847458 | D25: =IF(MAX(D$6:D$15)=MIN(D$6:D$15),0,(D11-MIN(D$6:D$15))/(MAX(D$6:D$15)-MIN(D$6:D$15))) -> 0.45 | E25: =IF(MAX(E$6:E$15)=MIN(E$6:E$15),0,(E11-MIN(E$6:E$15))/(MAX(E$6:E$15)-MIN(E$6:E$15))) -> 0.29268293 | F25: =IF(MAX(F$6:F$15)=MIN(F$6:F$15),0,(F11-MIN(F$6:F$15))/(MAX(F$6:F$15)-MIN(F$6:F$15))) -> 0.375 | G25: =IF(MAX(G$6:G$15)=MIN(G$6:G$15),0,(G11-MIN(G$6:G$15))/(MAX(G$6:G$15)-MIN(G$6:G$15))) -> 0.29508197 | H25: 1
A26: S7 | B26: =IF(MAX(B$6:B$15)=MIN(B$6:B$15),0,(B12-MIN(B$6:B$15))/(MAX(B$6:B$15)-MIN(B$6:B$15))) -> 0.31067961 | C26: =IF(MAX(C$6:C$15)=MIN(C$6:C$15),0,(C12-MIN(C$6:C$15))/(MAX(C$6:C$15)-MIN(C$6:C$15))) -> 0.28813559 | D26: =IF(MAX(D$6:D$15)=MIN(D$6:D$15),0,(D12-MIN(D$6:D$15))/(MAX(D$6:D$15)-MIN(D$6:D$15))) -> 0 | E26: =IF(MAX(E$6:E$15)=MIN(E$6:E$15),0,(E12-MIN(E$6:E$15))/(MAX(E$6:E$15)-MIN(E$6:E$15))) -> 0 | F26: =IF(MAX(F$6:F$15)=MIN(F$6:F$15),0,(F12-MIN(F$6:F$15))/(MAX(F$6:F$15)-MIN(F$6:F$15))) -> 0.16071429 | G26: =IF(MAX(G$6:G$15)=MIN(G$6:G$15),0,(G12-MIN(G$6:G$15))/(MAX(G$6:G$15)-MIN(G$6:G$15))) -> 0 | H26: 1
A27: S8 | B27: =IF(MAX(B$6:B$15)=MIN(B$6:B$15),0,(B13-MIN(B$6:B$15))/(MAX(B$6:B$15)-MIN(B$6:B$15))) -> 0.33980583 | C27: =IF(MAX(C$6:C$15)=MIN(C$6:C$15),0,(C13-MIN(C$6:C$15))/(MAX(C$6:C$15)-MIN(C$6:C$15))) -> 0.44067797 | D27: =IF(MAX(D$6:D$15)=MIN(D$6:D$15),0,(D13-MIN(D$6:D$15))/(MAX(D$6:D$15)-MIN(D$6:D$15))) -> 0.075 | E27: =IF(MAX(E$6:E$15)=MIN(E$6:E$15),0,(E13-MIN(E$6:E$15))/(MAX(E$6:E$15)-MIN(E$6:E$15))) -> 0.048780488 | F27: =IF(MAX(F$6:F$15)=MIN(F$6:F$15),0,(F13-MIN(F$6:F$15))/(MAX(F$6:F$15)-MIN(F$6:F$15))) -> 0.26785714 | G27: =IF(MAX(G$6:G$15)=MIN(G$6:G$15),0,(G13-MIN(G$6:G$15))/(MAX(G$6:G$15)-MIN(G$6:G$15))) -> 0.27868852 | H27: 1
A28: S9 | B28: =IF(MAX(B$6:B$15)=MIN(B$6:B$15),0,(B14-MIN(B$6:B$15))/(MAX(B$6:B$15)-MIN(B$6:B$15))) -> 0.96116505 | C28: =IF(MAX(C$6:C$15)=MIN(C$6:C$15),0,(C14-MIN(C$6:C$15))/(MAX(C$6:C$15)-MIN(C$6:C$15))) -> 0.98305085 | D28: =IF(MAX(D$6:D$15)=MIN(D$6:D$15),0,(D14-MIN(D$6:D$15))/(MAX(D$6:D$15)-MIN(D$6:D$15))) -> 0.675 | E28: =IF(MAX(E$6:E$15)=MIN(E$6:E$15),0,(E14-MIN(E$6:E$15))/(MAX(E$6:E$15)-MIN(E$6:E$15))) -> 0.92682927 | F28: =IF(MAX(F$6:F$15)=MIN(F$6:F$15),0,(F14-MIN(F$6:F$15))/(MAX(F$6:F$15)-MIN(F$6:F$15))) -> 0.67857143 | G28: =IF(MAX(G$6:G$15)=MIN(G$6:G$15),0,(G14-MIN(G$6:G$15))/(MAX(G$6:G$15)-MIN(G$6:G$15))) -> 0.90163934 | H28: 2
A29: S10 | B29: =IF(MAX(B$6:B$15)=MIN(B$6:B$15),0,(B15-MIN(B$6:B$15))/(MAX(B$6:B$15)-MIN(B$6:B$15))) -> 1 | C29: =IF(MAX(C$6:C$15)=MIN(C$6:C$15),0,(C15-MIN(C$6:C$15))/(MAX(C$6:C$15)-MIN(C$6:C$15))) -> 1 | D29: =IF(MAX(D$6:D$15)=MIN(D$6:D$15),0,(D15-MIN(D$6:D$15))/(MAX(D$6:D$15)-MIN(D$6:D$15))) -> 0.7 | E29: =IF(MAX(E$6:E$15)=MIN(E$6:E$15),0,(E15-MIN(E$6:E$15))/(MAX(E$6:E$15)-MIN(E$6:E$15))) -> 1 | F29: =IF(MAX(F$6:F$15)=MIN(F$6:F$15),0,(F15-MIN(F$6:F$15))/(MAX(F$6:F$15)-MIN(F$6:F$15))) -> 1 | G29: =IF(MAX(G$6:G$15)=MIN(G$6:G$15),0,(G15-MIN(G$6:G$15))/(MAX(G$6:G$15)-MIN(G$6:G$15))) -> 0.40983607 | H29: 2
A32: Source: original Codex experiment workbook, Dataset!B3:H12. All recorded measurements and class assignments are preserved.
A33: Workflow follows the project’s 11 result tabs, with all four metrics and paired None / MinMax analysis.
A34: Neighbor order, observed groups and PCA coordinates are project outputs for this recorded experiment. Formula-linked calculations show the remaining steps.
A35: Neighbors exclude the target and resolve equal distances by original index. b(k) = 1 only when a(k) / k > 0.5. Distances retain full precision.

Sheet Distances
A2: 02 Distances
A4: Euclidean (None)
A5: Object | B5: S1 | C5: S2 | D5: S3 | E5: S4 | F5: S5 | G5: S6 | H5: S7 | I5: S8 | J5: S9 | K5: S10
A6: S1 | B6: =SQRT(SUM((Dataset!B6-Dataset!B6)^2,(Dataset!C6-Dataset!C6)^2,(Dataset!D6-Dataset!D6)^2,(Dataset!E6-Dataset!E6)^2,(Dataset!F6-Dataset!F6)^2,(Dataset!G6-Dataset!G6)^2)) -> 0 | C6: =SQRT(SUM((Dataset!B6-Dataset!B7)^2,(Dataset!C6-Dataset!C7)^2,(Dataset!D6-Dataset!D7)^2,(Dataset!E6-Dataset!E7)^2,(Dataset!F6-Dataset!F7)^2,(Dataset!G6-Dataset!G7)^2)) -> 33.294744 | D6: =SQRT(SUM((Dataset!B6-Dataset!B8)^2,(Dataset!C6-Dataset!C8)^2,(Dataset!D6-Dataset!D8)^2,(Dataset!E6-Dataset!E8)^2,(Dataset!F6-Dataset!F8)^2,(Dataset!G6-Dataset!G8)^2)) -> 84.512366 | E6: =SQRT(SUM((Dataset!B6-Dataset!B9)^2,(Dataset!C6-Dataset!C9)^2,(Dataset!D6-Dataset!D9)^2,(Dataset!E6-Dataset!E9)^2,(Dataset!F6-Dataset!F9)^2,(Dataset!G6-Dataset!G9)^2)) -> 52.837297 | F6: =SQRT(SUM((Dataset!B6-Dataset!B10)^2,(Dataset!C6-Dataset!C10)^2,(Dataset!D6-Dataset!D10)^2,(Dataset!E6-Dataset!E10)^2,(Dataset!F6-Dataset!F10)^2,(Dataset!G6-Dataset!G10)^2)) -> 113.28327 | G6: =SQRT(SUM((Dataset!B6-Dataset!B11)^2,(Dataset!C6-Dataset!C11)^2,(Dataset!D6-Dataset!D11)^2,(Dataset!E6-Dataset!E11)^2,(Dataset!F6-Dataset!F11)^2,(Dataset!G6-Dataset!G11)^2)) -> 69.816975 | H6: =SQRT(SUM((Dataset!B6-Dataset!B12)^2,(Dataset!C6-Dataset!C12)^2,(Dataset!D6-Dataset!D12)^2,(Dataset!E6-Dataset!E12)^2,(Dataset!F6-Dataset!F12)^2,(Dataset!G6-Dataset!G12)^2)) -> 53.987128 | I6: =SQRT(SUM((Dataset!B6-Dataset!B13)^2,(Dataset!C6-Dataset!C13)^2,(Dataset!D6-Dataset!D13)^2,(Dataset!E6-Dataset!E13)^2,(Dataset!F6-Dataset!F13)^2,(Dataset!G6-Dataset!G13)^2)) -> 57.210663 | J6: =SQRT(SUM((Dataset!B6-Dataset!B14)^2,(Dataset!C6-Dataset!C14)^2,(Dataset!D6-Dataset!D14)^2,(Dataset!E6-Dataset!E14)^2,(Dataset!F6-Dataset!F14)^2,(Dataset!G6-Dataset!G14)^2)) -> 115.85495 | K6: =SQRT(SUM((Dataset!B6-Dataset!B15)^2,(Dataset!C6-Dataset!C15)^2,(Dataset!D6-Dataset!D15)^2,(Dataset!E6-Dataset!E15)^2,(Dataset!F6-Dataset!F15)^2,(Dataset!G6-Dataset!G15)^2)) -> 119.70418
A7: S2 | B7: =SQRT(SUM((Dataset!B7-Dataset!B6)^2,(Dataset!C7-Dataset!C6)^2,(Dataset!D7-Dataset!D6)^2,(Dataset!E7-Dataset!E6)^2,(Dataset!F7-Dataset!F6)^2,(Dataset!G7-Dataset!G6)^2)) -> 33.294744 | C7: =SQRT(SUM((Dataset!B7-Dataset!B7)^2,(Dataset!C7-Dataset!C7)^2,(Dataset!D7-Dataset!D7)^2,(Dataset!E7-Dataset!E7)^2,(Dataset!F7-Dataset!F7)^2,(Dataset!G7-Dataset!G7)^2)) -> 0 | D7: =SQRT(SUM((Dataset!B7-Dataset!B8)^2,(Dataset!C7-Dataset!C8)^2,(Dataset!D7-Dataset!D8)^2,(Dataset!E7-Dataset!E8)^2,(Dataset!F7-Dataset!F8)^2,(Dataset!G7-Dataset!G8)^2)) -> 54.899545 | E7: =SQRT(SUM((Dataset!B7-Dataset!B9)^2,(Dataset!C7-Dataset!C9)^2,(Dataset!D7-Dataset!D9)^2,(Dataset!E7-Dataset!E9)^2,(Dataset!F7-Dataset!F9)^2,(Dataset!G7-Dataset!G9)^2)) -> 21.409811 | F7: =SQRT(SUM((Dataset!B7-Dataset!B10)^2,(Dataset!C7-Dataset!C10)^2,(Dataset!D7-Dataset!D10)^2,(Dataset!E7-Dataset!E10)^2,(Dataset!F7-Dataset!F10)^2,(Dataset!G7-Dataset!G10)^2)) -> 84.909481 | G7: =SQRT(SUM((Dataset!B7-Dataset!B11)^2,(Dataset!C7-Dataset!C11)^2,(Dataset!D7-Dataset!D11)^2,(Dataset!E7-Dataset!E11)^2,(Dataset!F7-Dataset!F11)^2,(Dataset!G7-Dataset!G11)^2)) -> 39.609973 | H7: =SQRT(SUM((Dataset!B7-Dataset!B12)^2,(Dataset!C7-Dataset!C12)^2,(Dataset!D7-Dataset!D12)^2,(Dataset!E7-Dataset!E12)^2,(Dataset!F7-Dataset!F12)^2,(Dataset!G7-Dataset!G12)^2)) -> 23.750158 | I7: =SQRT(SUM((Dataset!B7-Dataset!B13)^2,(Dataset!C7-Dataset!C13)^2,(Dataset!D7-Dataset!D13)^2,(Dataset!E7-Dataset!E13)^2,(Dataset!F7-Dataset!F13)^2,(Dataset!G7-Dataset!G13)^2)) -> 26.300951 | J7: =SQRT(SUM((Dataset!B7-Dataset!B14)^2,(Dataset!C7-Dataset!C14)^2,(Dataset!D7-Dataset!D14)^2,(Dataset!E7-Dataset!E14)^2,(Dataset!F7-Dataset!F14)^2,(Dataset!G7-Dataset!G14)^2)) -> 88.559189 | K7: =SQRT(SUM((Dataset!B7-Dataset!B15)^2,(Dataset!C7-Dataset!C15)^2,(Dataset!D7-Dataset!D15)^2,(Dataset!E7-Dataset!E15)^2,(Dataset!F7-Dataset!F15)^2,(Dataset!G7-Dataset!G15)^2)) -> 92.573484
A8: S3 | B8: =SQRT(SUM((Dataset!B8-Dataset!B6)^2,(Dataset!C8-Dataset!C6)^2,(Dataset!D8-Dataset!D6)^2,(Dataset!E8-Dataset!E6)^2,(Dataset!F8-Dataset!F6)^2,(Dataset!G8-Dataset!G6)^2)) -> 84.512366 | C8: =SQRT(SUM((Dataset!B8-Dataset!B7)^2,(Dataset!C8-Dataset!C7)^2,(Dataset!D8-Dataset!D7)^2,(Dataset!E8-Dataset!E7)^2,(Dataset!F8-Dataset!F7)^2,(Dataset!G8-Dataset!G7)^2)) -> 54.899545 | D8: =SQRT(SUM((Dataset!B8-Dataset!B8)^2,(Dataset!C8-Dataset!C8)^2,(Dataset!D8-Dataset!D8)^2,(Dataset!E8-Dataset!E8)^2,(Dataset!F8-Dataset!F8)^2,(Dataset!G8-Dataset!G8)^2)) -> 0 | E8: =SQRT(SUM((Dataset!B8-Dataset!B9)^2,(Dataset!C8-Dataset!C9)^2,(Dataset!D8-Dataset!D9)^2,(Dataset!E8-Dataset!E9)^2,(Dataset!F8-Dataset!F9)^2,(Dataset!G8-Dataset!G9)^2)) -> 34.882374 | F8: =SQRT(SUM((Dataset!B8-Dataset!B10)^2,(Dataset!C8-Dataset!C10)^2,(Dataset!D8-Dataset!D10)^2,(Dataset!E8-Dataset!E10)^2,(Dataset!F8-Dataset!F10)^2,(Dataset!G8-Dataset!G10)^2)) -> 30.77174 | G8: =SQRT(SUM((Dataset!B8-Dataset!B11)^2,(Dataset!C8-Dataset!C11)^2,(Dataset!D8-Dataset!D11)^2,(Dataset!E8-Dataset!E11)^2,(Dataset!F8-Dataset!F11)^2,(Dataset!G8-Dataset!G11)^2)) -> 16.691016 | H8: =SQRT(SUM((Dataset!B8-Dataset!B12)^2,(Dataset!C8-Dataset!C12)^2,(Dataset!D8-Dataset!D12)^2,(Dataset!E8-Dataset!E12)^2,(Dataset!F8-Dataset!F12)^2,(Dataset!G8-Dataset!G12)^2)) -> 49.288031 | I8: =SQRT(SUM((Dataset!B8-Dataset!B13)^2,(Dataset!C8-Dataset!C13)^2,(Dataset!D8-Dataset!D13)^2,(Dataset!E8-Dataset!E13)^2,(Dataset!F8-Dataset!F13)^2,(Dataset!G8-Dataset!G13)^2)) -> 41.646849 | J8: =SQRT(SUM((Dataset!B8-Dataset!B14)^2,(Dataset!C8-Dataset!C14)^2,(Dataset!D8-Dataset!D14)^2,(Dataset!E8-Dataset!E14)^2,(Dataset!F8-Dataset!F14)^2,(Dataset!G8-Dataset!G14)^2)) -> 34.828867 | K8: =SQRT(SUM((Dataset!B8-Dataset!B15)^2,(Dataset!C8-Dataset!C15)^2,(Dataset!D8-Dataset!D15)^2,(Dataset!E8-Dataset!E15)^2,(Dataset!F8-Dataset!F15)^2,(Dataset!G8-Dataset!G15)^2)) -> 39.151117
A9: S4 | B9: =SQRT(SUM((Dataset!B9-Dataset!B6)^2,(Dataset!C9-Dataset!C6)^2,(Dataset!D9-Dataset!D6)^2,(Dataset!E9-Dataset!E6)^2,(Dataset!F9-Dataset!F6)^2,(Dataset!G9-Dataset!G6)^2)) -> 52.837297 | C9: =SQRT(SUM((Dataset!B9-Dataset!B7)^2,(Dataset!C9-Dataset!C7)^2,(Dataset!D9-Dataset!D7)^2,(Dataset!E9-Dataset!E7)^2,(Dataset!F9-Dataset!F7)^2,(Dataset!G9-Dataset!G7)^2)) -> 21.409811 | D9: =SQRT(SUM((Dataset!B9-Dataset!B8)^2,(Dataset!C9-Dataset!C8)^2,(Dataset!D9-Dataset!D8)^2,(Dataset!E9-Dataset!E8)^2,(Dataset!F9-Dataset!F8)^2,(Dataset!G9-Dataset!G8)^2)) -> 34.882374 | E9: =SQRT(SUM((Dataset!B9-Dataset!B9)^2,(Dataset!C9-Dataset!C9)^2,(Dataset!D9-Dataset!D9)^2,(Dataset!E9-Dataset!E9)^2,(Dataset!F9-Dataset!F9)^2,(Dataset!G9-Dataset!G9)^2)) -> 0 | F9: =SQRT(SUM((Dataset!B9-Dataset!B10)^2,(Dataset!C9-Dataset!C10)^2,(Dataset!D9-Dataset!D10)^2,(Dataset!E9-Dataset!E10)^2,(Dataset!F9-Dataset!F10)^2,(Dataset!G9-Dataset!G10)^2)) -> 65.205061 | G9: =SQRT(SUM((Dataset!B9-Dataset!B11)^2,(Dataset!C9-Dataset!C11)^2,(Dataset!D9-Dataset!D11)^2,(Dataset!E9-Dataset!E11)^2,(Dataset!F9-Dataset!F11)^2,(Dataset!G9-Dataset!G11)^2)) -> 19.538935 | H9: =SQRT(SUM((Dataset!B9-Dataset!B12)^2,(Dataset!C9-Dataset!C12)^2,(Dataset!D9-Dataset!D12)^2,(Dataset!E9-Dataset!E12)^2,(Dataset!F9-Dataset!F12)^2,(Dataset!G9-Dataset!G12)^2)) -> 19.547123 | I9: =SQRT(SUM((Dataset!B9-Dataset!B13)^2,(Dataset!C9-Dataset!C13)^2,(Dataset!D9-Dataset!D13)^2,(Dataset!E9-Dataset!E13)^2,(Dataset!F9-Dataset!F13)^2,(Dataset!G9-Dataset!G13)^2)) -> 14.688771 | J9: =SQRT(SUM((Dataset!B9-Dataset!B14)^2,(Dataset!C9-Dataset!C14)^2,(Dataset!D9-Dataset!D14)^2,(Dataset!E9-Dataset!E14)^2,(Dataset!F9-Dataset!F14)^2,(Dataset!G9-Dataset!G14)^2)) -> 69.067286 | K9: =SQRT(SUM((Dataset!B9-Dataset!B15)^2,(Dataset!C9-Dataset!C15)^2,(Dataset!D9-Dataset!D15)^2,(Dataset!E9-Dataset!E15)^2,(Dataset!F9-Dataset!F15)^2,(Dataset!G9-Dataset!G15)^2)) -> 73.206352
A10: S5 | B10: =SQRT(SUM((Dataset!B10-Dataset!B6)^2,(Dataset!C10-Dataset!C6)^2,(Dataset!D10-Dataset!D6)^2,(Dataset!E10-Dataset!E6)^2,(Dataset!F10-Dataset!F6)^2,(Dataset!G10-Dataset!G6)^2)) -> 113.28327 | C10: =SQRT(SUM((Dataset!B10-Dataset!B7)^2,(Dataset!C10-Dataset!C7)^2,(Dataset!D10-Dataset!D7)^2,(Dataset!E10-Dataset!E7)^2,(Dataset!F10-Dataset!F7)^2,(Dataset!G10-Dataset!G7)^2)) -> 84.909481 | D10: =SQRT(SUM((Dataset!B10-Dataset!B8)^2,(Dataset!C10-Dataset!C8)^2,(Dataset!D10-Dataset!D8)^2,(Dataset!E10-Dataset!E8)^2,(Dataset!F10-Dataset!F8)^2,(Dataset!G10-Dataset!G8)^2)) -> 30.77174 | E10: =SQRT(SUM((Dataset!B10-Dataset!B9)^2,(Dataset!C10-Dataset!C9)^2,(Dataset!D10-Dataset!D9)^2,(Dataset!E10-Dataset!E9)^2,(Dataset!F10-Dataset!F9)^2,(Dataset!G10-Dataset!G9)^2)) -> 65.205061 | F10: =SQRT(SUM((Dataset!B10-Dataset!B10)^2,(Dataset!C10-Dataset!C10)^2,(Dataset!D10-Dataset!D10)^2,(Dataset!E10-Dataset!E10)^2,(Dataset!F10-Dataset!F10)^2,(Dataset!G10-Dataset!G10)^2)) -> 0 | G10: =SQRT(SUM((Dataset!B10-Dataset!B11)^2,(Dataset!C10-Dataset!C11)^2,(Dataset!D10-Dataset!D11)^2,(Dataset!E10-Dataset!E11)^2,(Dataset!F10-Dataset!F11)^2,(Dataset!G10-Dataset!G11)^2)) -> 45.985759 | H10: =SQRT(SUM((Dataset!B10-Dataset!B12)^2,(Dataset!C10-Dataset!C12)^2,(Dataset!D10-Dataset!D12)^2,(Dataset!E10-Dataset!E12)^2,(Dataset!F10-Dataset!F12)^2,(Dataset!G10-Dataset!G12)^2)) -> 78.993734 | I10: =SQRT(SUM((Dataset!B10-Dataset!B13)^2,(Dataset!C10-Dataset!C13)^2,(Dataset!D10-Dataset!D13)^2,(Dataset!E10-Dataset!E13)^2,(Dataset!F10-Dataset!F13)^2,(Dataset!G10-Dataset!G13)^2)) -> 71.674403 | J10: =SQRT(SUM((Dataset!B10-Dataset!B14)^2,(Dataset!C10-Dataset!C14)^2,(Dataset!D10-Dataset!D14)^2,(Dataset!E10-Dataset!E14)^2,(Dataset!F10-Dataset!F14)^2,(Dataset!G10-Dataset!G14)^2)) -> 7.1547187 | K10: =SQRT(SUM((Dataset!B10-Dataset!B15)^2,(Dataset!C10-Dataset!C15)^2,(Dataset!D10-Dataset!D15)^2,(Dataset!E10-Dataset!E15)^2,(Dataset!F10-Dataset!F15)^2,(Dataset!G10-Dataset!G15)^2)) -> 10.437912
A11: S6 | B11: =SQRT(SUM((Dataset!B11-Dataset!B6)^2,(Dataset!C11-Dataset!C6)^2,(Dataset!D11-Dataset!D6)^2,(Dataset!E11-Dataset!E6)^2,(Dataset!F11-Dataset!F6)^2,(Dataset!G11-Dataset!G6)^2)) -> 69.816975 | C11: =SQRT(SUM((Dataset!B11-Dataset!B7)^2,(Dataset!C11-Dataset!C7)^2,(Dataset!D11-Dataset!D7)^2,(Dataset!E11-Dataset!E7)^2,(Dataset!F11-Dataset!F7)^2,(Dataset!G11-Dataset!G7)^2)) -> 39.609973 | D11: =SQRT(SUM((Dataset!B11-Dataset!B8)^2,(Dataset!C11-Dataset!C8)^2,(Dataset!D11-Dataset!D8)^2,(Dataset!E11-Dataset!E8)^2,(Dataset!F11-Dataset!F8)^2,(Dataset!G11-Dataset!G8)^2)) -> 16.691016 | E11: =SQRT(SUM((Dataset!B11-Dataset!B9)^2,(Dataset!C11-Dataset!C9)^2,(Dataset!D11-Dataset!D9)^2,(Dataset!E11-Dataset!E9)^2,(Dataset!F11-Dataset!F9)^2,(Dataset!G11-Dataset!G9)^2)) -> 19.538935 | F11: =SQRT(SUM((Dataset!B11-Dataset!B10)^2,(Dataset!C11-Dataset!C10)^2,(Dataset!D11-Dataset!D10)^2,(Dataset!E11-Dataset!E10)^2,(Dataset!F11-Dataset!F10)^2,(Dataset!G11-Dataset!G10)^2)) -> 45.985759 | G11: =SQRT(SUM((Dataset!B11-Dataset!B11)^2,(Dataset!C11-Dataset!C11)^2,(Dataset!D11-Dataset!D11)^2,(Dataset!E11-Dataset!E11)^2,(Dataset!F11-Dataset!F11)^2,(Dataset!G11-Dataset!G11)^2)) -> 0 | H11: =SQRT(SUM((Dataset!B11-Dataset!B12)^2,(Dataset!C11-Dataset!C12)^2,(Dataset!D11-Dataset!D12)^2,(Dataset!E11-Dataset!E12)^2,(Dataset!F11-Dataset!F12)^2,(Dataset!G11-Dataset!G12)^2)) -> 35.106125 | I11: =SQRT(SUM((Dataset!B11-Dataset!B13)^2,(Dataset!C11-Dataset!C13)^2,(Dataset!D11-Dataset!D13)^2,(Dataset!E11-Dataset!E13)^2,(Dataset!F11-Dataset!F13)^2,(Dataset!G11-Dataset!G13)^2)) -> 28.659553 | J11: =SQRT(SUM((Dataset!B11-Dataset!B14)^2,(Dataset!C11-Dataset!C14)^2,(Dataset!D11-Dataset!D14)^2,(Dataset!E11-Dataset!E14)^2,(Dataset!F11-Dataset!F14)^2,(Dataset!G11-Dataset!G14)^2)) -> 50.086126 | K11: =SQRT(SUM((Dataset!B11-Dataset!B15)^2,(Dataset!C11-Dataset!C15)^2,(Dataset!D11-Dataset!D15)^2,(Dataset!E11-Dataset!E15)^2,(Dataset!F11-Dataset!F15)^2,(Dataset!G11-Dataset!G15)^2)) -> 54.06829
A12: S7 | B12: =SQRT(SUM((Dataset!B12-Dataset!B6)^2,(Dataset!C12-Dataset!C6)^2,(Dataset!D12-Dataset!D6)^2,(Dataset!E12-Dataset!E6)^2,(Dataset!F12-Dataset!F6)^2,(Dataset!G12-Dataset!G6)^2)) -> 53.987128 | C12: =SQRT(SUM((Dataset!B12-Dataset!B7)^2,(Dataset!C12-Dataset!C7)^2,(Dataset!D12-Dataset!D7)^2,(Dataset!E12-Dataset!E7)^2,(Dataset!F12-Dataset!F7)^2,(Dataset!G12-Dataset!G7)^2)) -> 23.750158 | D12: =SQRT(SUM((Dataset!B12-Dataset!B8)^2,(Dataset!C12-Dataset!C8)^2,(Dataset!D12-Dataset!D8)^2,(Dataset!E12-Dataset!E8)^2,(Dataset!F12-Dataset!F8)^2,(Dataset!G12-Dataset!G8)^2)) -> 49.288031 | E12: =SQRT(SUM((Dataset!B12-Dataset!B9)^2,(Dataset!C12-Dataset!C9)^2,(Dataset!D12-Dataset!D9)^2,(Dataset!E12-Dataset!E9)^2,(Dataset!F12-Dataset!F9)^2,(Dataset!G12-Dataset!G9)^2)) -> 19.547123 | F12: =SQRT(SUM((Dataset!B12-Dataset!B10)^2,(Dataset!C12-Dataset!C10)^2,(Dataset!D12-Dataset!D10)^2,(Dataset!E12-Dataset!E10)^2,(Dataset!F12-Dataset!F10)^2,(Dataset!G12-Dataset!G10)^2)) -> 78.993734 | G12: =SQRT(SUM((Dataset!B12-Dataset!B11)^2,(Dataset!C12-Dataset!C11)^2,(Dataset!D12-Dataset!D11)^2,(Dataset!E12-Dataset!E11)^2,(Dataset!F12-Dataset!F11)^2,(Dataset!G12-Dataset!G11)^2)) -> 35.106125 | H12: =SQRT(SUM((Dataset!B12-Dataset!B12)^2,(Dataset!C12-Dataset!C12)^2,(Dataset!D12-Dataset!D12)^2,(Dataset!E12-Dataset!E12)^2,(Dataset!F12-Dataset!F12)^2,(Dataset!G12-Dataset!G12)^2)) -> 0 | I12: =SQRT(SUM((Dataset!B12-Dataset!B13)^2,(Dataset!C12-Dataset!C13)^2,(Dataset!D12-Dataset!D13)^2,(Dataset!E12-Dataset!E13)^2,(Dataset!F12-Dataset!F13)^2,(Dataset!G12-Dataset!G13)^2)) -> 10.119783 | J12: =SQRT(SUM((Dataset!B12-Dataset!B14)^2,(Dataset!C12-Dataset!C14)^2,(Dataset!D12-Dataset!D14)^2,(Dataset!E12-Dataset!E14)^2,(Dataset!F12-Dataset!F14)^2,(Dataset!G12-Dataset!G14)^2)) -> 83.638627 | K12: =SQRT(SUM((Dataset!B12-Dataset!B15)^2,(Dataset!C12-Dataset!C15)^2,(Dataset!D12-Dataset!D15)^2,(Dataset!E12-Dataset!E15)^2,(Dataset!F12-Dataset!F15)^2,(Dataset!G12-Dataset!G15)^2)) -> 87.661736
A13: S8 | B13: =SQRT(SUM((Dataset!B13-Dataset!B6)^2,(Dataset!C13-Dataset!C6)^2,(Dataset!D13-Dataset!D6)^2,(Dataset!E13-Dataset!E6)^2,(Dataset!F13-Dataset!F6)^2,(Dataset!G13-Dataset!G6)^2)) -> 57.210663 | C13: =SQRT(SUM((Dataset!B13-Dataset!B7)^2,(Dataset!C13-Dataset!C7)^2,(Dataset!D13-Dataset!D7)^2,(Dataset!E13-Dataset!E7)^2,(Dataset!F13-Dataset!F7)^2,(Dataset!G13-Dataset!G7)^2)) -> 26.300951 | D13: =SQRT(SUM((Dataset!B13-Dataset!B8)^2,(Dataset!C13-Dataset!C8)^2,(Dataset!D13-Dataset!D8)^2,(Dataset!E13-Dataset!E8)^2,(Dataset!F13-Dataset!F8)^2,(Dataset!G13-Dataset!G8)^2)) -> 41.646849 | E13: =SQRT(SUM((Dataset!B13-Dataset!B9)^2,(Dataset!C13-Dataset!C9)^2,(Dataset!D13-Dataset!D9)^2,(Dataset!E13-Dataset!E9)^2,(Dataset!F13-Dataset!F9)^2,(Dataset!G13-Dataset!G9)^2)) -> 14.688771 | F13: =SQRT(SUM((Dataset!B13-Dataset!B10)^2,(Dataset!C13-Dataset!C10)^2,(Dataset!D13-Dataset!D10)^2,(Dataset!E13-Dataset!E10)^2,(Dataset!F13-Dataset!F10)^2,(Dataset!G13-Dataset!G10)^2)) -> 71.674403 | G13: =SQRT(SUM((Dataset!B13-Dataset!B11)^2,(Dataset!C13-Dataset!C11)^2,(Dataset!D13-Dataset!D11)^2,(Dataset!E13-Dataset!E11)^2,(Dataset!F13-Dataset!F11)^2,(Dataset!G13-Dataset!G11)^2)) -> 28.659553 | H13: =SQRT(SUM((Dataset!B13-Dataset!B12)^2,(Dataset!C13-Dataset!C12)^2,(Dataset!D13-Dataset!D12)^2,(Dataset!E13-Dataset!E12)^2,(Dataset!F13-Dataset!F12)^2,(Dataset!G13-Dataset!G12)^2)) -> 10.119783 | I13: =SQRT(SUM((Dataset!B13-Dataset!B13)^2,(Dataset!C13-Dataset!C13)^2,(Dataset!D13-Dataset!D13)^2,(Dataset!E13-Dataset!E13)^2,(Dataset!F13-Dataset!F13)^2,(Dataset!G13-Dataset!G13)^2)) -> 0 | J13: =SQRT(SUM((Dataset!B13-Dataset!B14)^2,(Dataset!C13-Dataset!C14)^2,(Dataset!D13-Dataset!D14)^2,(Dataset!E13-Dataset!E14)^2,(Dataset!F13-Dataset!F14)^2,(Dataset!G13-Dataset!G14)^2)) -> 75.944519 | K13: =SQRT(SUM((Dataset!B13-Dataset!B15)^2,(Dataset!C13-Dataset!C15)^2,(Dataset!D13-Dataset!D15)^2,(Dataset!E13-Dataset!E15)^2,(Dataset!F13-Dataset!F15)^2,(Dataset!G13-Dataset!G15)^2)) -> 80.101748
A14: S9 | B14: =SQRT(SUM((Dataset!B14-Dataset!B6)^2,(Dataset!C14-Dataset!C6)^2,(Dataset!D14-Dataset!D6)^2,(Dataset!E14-Dataset!E6)^2,(Dataset!F14-Dataset!F6)^2,(Dataset!G14-Dataset!G6)^2)) -> 115.85495 | C14: =SQRT(SUM((Dataset!B14-Dataset!B7)^2,(Dataset!C14-Dataset!C7)^2,(Dataset!D14-Dataset!D7)^2,(Dataset!E14-Dataset!E7)^2,(Dataset!F14-Dataset!F7)^2,(Dataset!G14-Dataset!G7)^2)) -> 88.559189 | D14: =SQRT(SUM((Dataset!B14-Dataset!B8)^2,(Dataset!C14-Dataset!C8)^2,(Dataset!D14-Dataset!D8)^2,(Dataset!E14-Dataset!E8)^2,(Dataset!F14-Dataset!F8)^2,(Dataset!G14-Dataset!G8)^2)) -> 34.828867 | E14: =SQRT(SUM((Dataset!B14-Dataset!B9)^2,(Dataset!C14-Dataset!C9)^2,(Dataset!D14-Dataset!D9)^2,(Dataset!E14-Dataset!E9)^2,(Dataset!F14-Dataset!F9)^2,(Dataset!G14-Dataset!G9)^2)) -> 69.067286 | F14: =SQRT(SUM((Dataset!B14-Dataset!B10)^2,(Dataset!C14-Dataset!C10)^2,(Dataset!D14-Dataset!D10)^2,(Dataset!E14-Dataset!E10)^2,(Dataset!F14-Dataset!F10)^2,(Dataset!G14-Dataset!G10)^2)) -> 7.1547187 | G14: =SQRT(SUM((Dataset!B14-Dataset!B11)^2,(Dataset!C14-Dataset!C11)^2,(Dataset!D14-Dataset!D11)^2,(Dataset!E14-Dataset!E11)^2,(Dataset!F14-Dataset!F11)^2,(Dataset!G14-Dataset!G11)^2)) -> 50.086126 | H14: =SQRT(SUM((Dataset!B14-Dataset!B12)^2,(Dataset!C14-Dataset!C12)^2,(Dataset!D14-Dataset!D12)^2,(Dataset!E14-Dataset!E12)^2,(Dataset!F14-Dataset!F12)^2,(Dataset!G14-Dataset!G12)^2)) -> 83.638627 | I14: =SQRT(SUM((Dataset!B14-Dataset!B13)^2,(Dataset!C14-Dataset!C13)^2,(Dataset!D14-Dataset!D13)^2,(Dataset!E14-Dataset!E13)^2,(Dataset!F14-Dataset!F13)^2,(Dataset!G14-Dataset!G13)^2)) -> 75.944519 | J14: =SQRT(SUM((Dataset!B14-Dataset!B14)^2,(Dataset!C14-Dataset!C14)^2,(Dataset!D14-Dataset!D14)^2,(Dataset!E14-Dataset!E14)^2,(Dataset!F14-Dataset!F14)^2,(Dataset!G14-Dataset!G14)^2)) -> 0 | K14: =SQRT(SUM((Dataset!B14-Dataset!B15)^2,(Dataset!C14-Dataset!C15)^2,(Dataset!D14-Dataset!D15)^2,(Dataset!E14-Dataset!E15)^2,(Dataset!F14-Dataset!F15)^2,(Dataset!G14-Dataset!G15)^2)) -> 5.5317267
A15: S10 | B15: =SQRT(SUM((Dataset!B15-Dataset!B6)^2,(Dataset!C15-Dataset!C6)^2,(Dataset!D15-Dataset!D6)^2,(Dataset!E15-Dataset!E6)^2,(Dataset!F15-Dataset!F6)^2,(Dataset!G15-Dataset!G6)^2)) -> 119.70418 | C15: =SQRT(SUM((Dataset!B15-Dataset!B7)^2,(Dataset!C15-Dataset!C7)^2,(Dataset!D15-Dataset!D7)^2,(Dataset!E15-Dataset!E7)^2,(Dataset!F15-Dataset!F7)^2,(Dataset!G15-Dataset!G7)^2)) -> 92.573484 | D15: =SQRT(SUM((Dataset!B15-Dataset!B8)^2,(Dataset!C15-Dataset!C8)^2,(Dataset!D15-Dataset!D8)^2,(Dataset!E15-Dataset!E8)^2,(Dataset!F15-Dataset!F8)^2,(Dataset!G15-Dataset!G8)^2)) -> 39.151117 | E15: =SQRT(SUM((Dataset!B15-Dataset!B9)^2,(Dataset!C15-Dataset!C9)^2,(Dataset!D15-Dataset!D9)^2,(Dataset!E15-Dataset!E9)^2,(Dataset!F15-Dataset!F9)^2,(Dataset!G15-Dataset!G9)^2)) -> 73.206352 | F15: =SQRT(SUM((Dataset!B15-Dataset!B10)^2,(Dataset!C15-Dataset!C10)^2,(Dataset!D15-Dataset!D10)^2,(Dataset!E15-Dataset!E10)^2,(Dataset!F15-Dataset!F10)^2,(Dataset!G15-Dataset!G10)^2)) -> 10.437912 | G15: =SQRT(SUM((Dataset!B15-Dataset!B11)^2,(Dataset!C15-Dataset!C11)^2,(Dataset!D15-Dataset!D11)^2,(Dataset!E15-Dataset!E11)^2,(Dataset!F15-Dataset!F11)^2,(Dataset!G15-Dataset!G11)^2)) -> 54.06829 | H15: =SQRT(SUM((Dataset!B15-Dataset!B12)^2,(Dataset!C15-Dataset!C12)^2,(Dataset!D15-Dataset!D12)^2,(Dataset!E15-Dataset!E12)^2,(Dataset!F15-Dataset!F12)^2,(Dataset!G15-Dataset!G12)^2)) -> 87.661736 | I15: =SQRT(SUM((Dataset!B15-Dataset!B13)^2,(Dataset!C15-Dataset!C13)^2,(Dataset!D15-Dataset!D13)^2,(Dataset!E15-Dataset!E13)^2,(Dataset!F15-Dataset!F13)^2,(Dataset!G15-Dataset!G13)^2)) -> 80.101748 | J15: =SQRT(SUM((Dataset!B15-Dataset!B14)^2,(Dataset!C15-Dataset!C14)^2,(Dataset!D15-Dataset!D14)^2,(Dataset!E15-Dataset!E14)^2,(Dataset!F15-Dataset!F14)^2,(Dataset!G15-Dataset!G14)^2)) -> 5.5317267 | K15: =SQRT(SUM((Dataset!B15-Dataset!B15)^2,(Dataset!C15-Dataset!C15)^2,(Dataset!D15-Dataset!D15)^2,(Dataset!E15-Dataset!E15)^2,(Dataset!F15-Dataset!F15)^2,(Dataset!G15-Dataset!G15)^2)) -> 0
A19: Chebyshev (None)
A20: Object | B20: S1 | C20: S2 | D20: S3 | E20: S4 | F20: S5 | G20: S6 | H20: S7 | I20: S8 | J20: S9 | K20: S10
A21: S1 | B21: =MAX(ABS(Dataset!B6-Dataset!B6),ABS(Dataset!C6-Dataset!C6),ABS(Dataset!D6-Dataset!D6),ABS(Dataset!E6-Dataset!E6),ABS(Dataset!F6-Dataset!F6),ABS(Dataset!G6-Dataset!G6)) -> 0 | C21: =MAX(ABS(Dataset!B6-Dataset!B7),ABS(Dataset!C6-Dataset!C7),ABS(Dataset!D6-Dataset!D7),ABS(Dataset!E6-Dataset!E7),ABS(Dataset!F6-Dataset!F7),ABS(Dataset!G6-Dataset!G7)) -> 25 | D21: =MAX(ABS(Dataset!B6-Dataset!B8),ABS(Dataset!C6-Dataset!C8),ABS(Dataset!D6-Dataset!D8),ABS(Dataset!E6-Dataset!E8),ABS(Dataset!F6-Dataset!F8),ABS(Dataset!G6-Dataset!G8)) -> 70 | E21: =MAX(ABS(Dataset!B6-Dataset!B9),ABS(Dataset!C6-Dataset!C9),ABS(Dataset!D6-Dataset!D9),ABS(Dataset!E6-Dataset!E9),ABS(Dataset!F6-Dataset!F9),ABS(Dataset!G6-Dataset!G9)) -> 41 | F21: =MAX(ABS(Dataset!B6-Dataset!B10),ABS(Dataset!C6-Dataset!C10),ABS(Dataset!D6-Dataset!D10),ABS(Dataset!E6-Dataset!E10),ABS(Dataset!F6-Dataset!F10),ABS(Dataset!G6-Dataset!G10)) -> 98 | G21: =MAX(ABS(Dataset!B6-Dataset!B11),ABS(Dataset!C6-Dataset!C11),ABS(Dataset!D6-Dataset!D11),ABS(Dataset!E6-Dataset!E11),ABS(Dataset!F6-Dataset!F11),ABS(Dataset!G6-Dataset!G11)) -> 59 | H21: =MAX(ABS(Dataset!B6-Dataset!B12),ABS(Dataset!C6-Dataset!C12),ABS(Dataset!D6-Dataset!D12),ABS(Dataset!E6-Dataset!E12),ABS(Dataset!F6-Dataset!F12),ABS(Dataset!G6-Dataset!G12)) -> 40 | I21: =MAX(ABS(Dataset!B6-Dataset!B13),ABS(Dataset!C6-Dataset!C13),ABS(Dataset!D6-Dataset!D13),ABS(Dataset!E6-Dataset!E13),ABS(Dataset!F6-Dataset!F13),ABS(Dataset!G6-Dataset!G13)) -> 37 | J21: =MAX(ABS(Dataset!B6-Dataset!B14),ABS(Dataset!C6-Dataset!C14),ABS(Dataset!D6-Dataset!D14),ABS(Dataset!E6-Dataset!E14),ABS(Dataset!F6-Dataset!F14),ABS(Dataset!G6-Dataset!G14)) -> 99 | K21: =MAX(ABS(Dataset!B6-Dataset!B15),ABS(Dataset!C6-Dataset!C15),ABS(Dataset!D6-Dataset!D15),ABS(Dataset!E6-Dataset!E15),ABS(Dataset!F6-Dataset!F15),ABS(Dataset!G6-Dataset!G15)) -> 103
A22: S2 | B22: =MAX(ABS(Dataset!B7-Dataset!B6),ABS(Dataset!C7-Dataset!C6),ABS(Dataset!D7-Dataset!D6),ABS(Dataset!E7-Dataset!E6),ABS(Dataset!F7-Dataset!F6),ABS(Dataset!G7-Dataset!G6)) -> 25 | C22: =MAX(ABS(Dataset!B7-Dataset!B7),ABS(Dataset!C7-Dataset!C7),ABS(Dataset!D7-Dataset!D7),ABS(Dataset!E7-Dataset!E7),ABS(Dataset!F7-Dataset!F7),ABS(Dataset!G7-Dataset!G7)) -> 0 | D22: =MAX(ABS(Dataset!B7-Dataset!B8),ABS(Dataset!C7-Dataset!C8),ABS(Dataset!D7-Dataset!D8),ABS(Dataset!E7-Dataset!E8),ABS(Dataset!F7-Dataset!F8),ABS(Dataset!G7-Dataset!G8)) -> 45 | E22: =MAX(ABS(Dataset!B7-Dataset!B9),ABS(Dataset!C7-Dataset!C9),ABS(Dataset!D7-Dataset!D9),ABS(Dataset!E7-Dataset!E9),ABS(Dataset!F7-Dataset!F9),ABS(Dataset!G7-Dataset!G9)) -> 16 | F22: =MAX(ABS(Dataset!B7-Dataset!B10),ABS(Dataset!C7-Dataset!C10),ABS(Dataset!D7-Dataset!D10),ABS(Dataset!E7-Dataset!E10),ABS(Dataset!F7-Dataset!F10),ABS(Dataset!G7-Dataset!G10)) -> 73 | G22: =MAX(ABS(Dataset!B7-Dataset!B11),ABS(Dataset!C7-Dataset!C11),ABS(Dataset!D7-Dataset!D11),ABS(Dataset!E7-Dataset!E11),ABS(Dataset!F7-Dataset!F11),ABS(Dataset!G7-Dataset!G11)) -> 34 | H22: =MAX(ABS(Dataset!B7-Dataset!B12),ABS(Dataset!C7-Dataset!C12),ABS(Dataset!D7-Dataset!D12),ABS(Dataset!E7-Dataset!E12),ABS(Dataset!F7-Dataset!F12),ABS(Dataset!G7-Dataset!G12)) -> 21 | I22: =MAX(ABS(Dataset!B7-Dataset!B13),ABS(Dataset!C7-Dataset!C13),ABS(Dataset!D7-Dataset!D13),ABS(Dataset!E7-Dataset!E13),ABS(Dataset!F7-Dataset!F13),ABS(Dataset!G7-Dataset!G13)) -> 18 | J22: =MAX(ABS(Dataset!B7-Dataset!B14),ABS(Dataset!C7-Dataset!C14),ABS(Dataset!D7-Dataset!D14),ABS(Dataset!E7-Dataset!E14),ABS(Dataset!F7-Dataset!F14),ABS(Dataset!G7-Dataset!G14)) -> 74 | K22: =MAX(ABS(Dataset!B7-Dataset!B15),ABS(Dataset!C7-Dataset!C15),ABS(Dataset!D7-Dataset!D15),ABS(Dataset!E7-Dataset!E15),ABS(Dataset!F7-Dataset!F15),ABS(Dataset!G7-Dataset!G15)) -> 78
A23: S3 | B23: =MAX(ABS(Dataset!B8-Dataset!B6),ABS(Dataset!C8-Dataset!C6),ABS(Dataset!D8-Dataset!D6),ABS(Dataset!E8-Dataset!E6),ABS(Dataset!F8-Dataset!F6),ABS(Dataset!G8-Dataset!G6)) -> 70 | C23: =MAX(ABS(Dataset!B8-Dataset!B7),ABS(Dataset!C8-Dataset!C7),ABS(Dataset!D8-Dataset!D7),ABS(Dataset!E8-Dataset!E7),ABS(Dataset!F8-Dataset!F7),ABS(Dataset!G8-Dataset!G7)) -> 45 | D23: =MAX(ABS(Dataset!B8-Dataset!B8),ABS(Dataset!C8-Dataset!C8),ABS(Dataset!D8-Dataset!D8),ABS(Dataset!E8-Dataset!E8),ABS(Dataset!F8-Dataset!F8),ABS(Dataset!G8-Dataset!G8)) -> 0 | E23: =MAX(ABS(Dataset!B8-Dataset!B9),ABS(Dataset!C8-Dataset!C9),ABS(Dataset!D8-Dataset!D9),ABS(Dataset!E8-Dataset!E9),ABS(Dataset!F8-Dataset!F9),ABS(Dataset!G8-Dataset!G9)) -> 29 | F23: =MAX(ABS(Dataset!B8-Dataset!B10),ABS(Dataset!C8-Dataset!C10),ABS(Dataset!D8-Dataset!D10),ABS(Dataset!E8-Dataset!E10),ABS(Dataset!F8-Dataset!F10),ABS(Dataset!G8-Dataset!G10)) -> 28 | G23: =MAX(ABS(Dataset!B8-Dataset!B11),ABS(Dataset!C8-Dataset!C11),ABS(Dataset!D8-Dataset!D11),ABS(Dataset!E8-Dataset!E11),ABS(Dataset!F8-Dataset!F11),ABS(Dataset!G8-Dataset!G11)) -> 11 | H23: =MAX(ABS(Dataset!B8-Dataset!B12),ABS(Dataset!C8-Dataset!C12),ABS(Dataset!D8-Dataset!D12),ABS(Dataset!E8-Dataset!E12),ABS(Dataset!F8-Dataset!F12),ABS(Dataset!G8-Dataset!G12)) -> 38 | I23: =MAX(ABS(Dataset!B8-Dataset!B13),ABS(Dataset!C8-Dataset!C13),ABS(Dataset!D8-Dataset!D13),ABS(Dataset!E8-Dataset!E13),ABS(Dataset!F8-Dataset!F13),ABS(Dataset!G8-Dataset!G13)) -> 35 | J23: =MAX(ABS(Dataset!B8-Dataset!B14),ABS(Dataset!C8-Dataset!C14),ABS(Dataset!D8-Dataset!D14),ABS(Dataset!E8-Dataset!E14),ABS(Dataset!F8-Dataset!F14),ABS(Dataset!G8-Dataset!G14)) -> 29 | K23: =MAX(ABS(Dataset!B8-Dataset!B15),ABS(Dataset!C8-Dataset!C15),ABS(Dataset!D8-Dataset!D15),ABS(Dataset!E8-Dataset!E15),ABS(Dataset!F8-Dataset!F15),ABS(Dataset!G8-Dataset!G15)) -> 33
A24: S4 | B24: =MAX(ABS(Dataset!B9-Dataset!B6),ABS(Dataset!C9-Dataset!C6),ABS(Dataset!D9-Dataset!D6),ABS(Dataset!E9-Dataset!E6),ABS(Dataset!F9-Dataset!F6),ABS(Dataset!G9-Dataset!G6)) -> 41 | C24: =MAX(ABS(Dataset!B9-Dataset!B7),ABS(Dataset!C9-Dataset!C7),ABS(Dataset!D9-Dataset!D7),ABS(Dataset!E9-Dataset!E7),ABS(Dataset!F9-Dataset!F7),ABS(Dataset!G9-Dataset!G7)) -> 16 | D24: =MAX(ABS(Dataset!B9-Dataset!B8),ABS(Dataset!C9-Dataset!C8),ABS(Dataset!D9-Dataset!D8),ABS(Dataset!E9-Dataset!E8),ABS(Dataset!F9-Dataset!F8),ABS(Dataset!G9-Dataset!G8)) -> 29 | E24: =MAX(ABS(Dataset!B9-Dataset!B9),ABS(Dataset!C9-Dataset!C9),ABS(Dataset!D9-Dataset!D9),ABS(Dataset!E9-Dataset!E9),ABS(Dataset!F9-Dataset!F9),ABS(Dataset!G9-Dataset!G9)) -> 0 | F24: =MAX(ABS(Dataset!B9-Dataset!B10),ABS(Dataset!C9-Dataset!C10),ABS(Dataset!D9-Dataset!D10),ABS(Dataset!E9-Dataset!E10),ABS(Dataset!F9-Dataset!F10),ABS(Dataset!G9-Dataset!G10)) -> 57 | G24: =MAX(ABS(Dataset!B9-Dataset!B11),ABS(Dataset!C9-Dataset!C11),ABS(Dataset!D9-Dataset!D11),ABS(Dataset!E9-Dataset!E11),ABS(Dataset!F9-Dataset!F11),ABS(Dataset!G9-Dataset!G11)) -> 18 | H24: =MAX(ABS(Dataset!B9-Dataset!B12),ABS(Dataset!C9-Dataset!C12),ABS(Dataset!D9-Dataset!D12),ABS(Dataset!E9-Dataset!E12),ABS(Dataset!F9-Dataset!F12),ABS(Dataset!G9-Dataset!G12)) -> 16 | I24: =MAX(ABS(Dataset!B9-Dataset!B13),ABS(Dataset!C9-Dataset!C13),ABS(Dataset!D9-Dataset!D13),ABS(Dataset!E9-Dataset!E13),ABS(Dataset!F9-Dataset!F13),ABS(Dataset!G9-Dataset!G13)) -> 13 | J24: =MAX(ABS(Dataset!B9-Dataset!B14),ABS(Dataset!C9-Dataset!C14),ABS(Dataset!D9-Dataset!D14),ABS(Dataset!E9-Dataset!E14),ABS(Dataset!F9-Dataset!F14),ABS(Dataset!G9-Dataset!G14)) -> 58 | K24: =MAX(ABS(Dataset!B9-Dataset!B15),ABS(Dataset!C9-Dataset!C15),ABS(Dataset!D9-Dataset!D15),ABS(Dataset!E9-Dataset!E15),ABS(Dataset!F9-Dataset!F15),ABS(Dataset!G9-Dataset!G15)) -> 62
A25: S5 | B25: =MAX(ABS(Dataset!B10-Dataset!B6),ABS(Dataset!C10-Dataset!C6),ABS(Dataset!D10-Dataset!D6),ABS(Dataset!E10-Dataset!E6),ABS(Dataset!F10-Dataset!F6),ABS(Dataset!G10-Dataset!G6)) -> 98 | C25: =MAX(ABS(Dataset!B10-Dataset!B7),ABS(Dataset!C10-Dataset!C7),ABS(Dataset!D10-Dataset!D7),ABS(Dataset!E10-Dataset!E7),ABS(Dataset!F10-Dataset!F7),ABS(Dataset!G10-Dataset!G7)) -> 73 | D25: =MAX(ABS(Dataset!B10-Dataset!B8),ABS(Dataset!C10-Dataset!C8),ABS(Dataset!D10-Dataset!D8),ABS(Dataset!E10-Dataset!E8),ABS(Dataset!F10-Dataset!F8),ABS(Dataset!G10-Dataset!G8)) -> 28 | E25: =MAX(ABS(Dataset!B10-Dataset!B9),ABS(Dataset!C10-Dataset!C9),ABS(Dataset!D10-Dataset!D9),ABS(Dataset!E10-Dataset!E9),ABS(Dataset!F10-Dataset!F9),ABS(Dataset!G10-Dataset!G9)) -> 57 | F25: =MAX(ABS(Dataset!B10-Dataset!B10),ABS(Dataset!C10-Dataset!C10),ABS(Dataset!D10-Dataset!D10),ABS(Dataset!E10-Dataset!E10),ABS(Dataset!F10-Dataset!F10),ABS(Dataset!G10-Dataset!G10)) -> 0 | G25: =MAX(ABS(Dataset!B10-Dataset!B11),ABS(Dataset!C10-Dataset!C11),ABS(Dataset!D10-Dataset!D11),ABS(Dataset!E10-Dataset!E11),ABS(Dataset!F10-Dataset!F11),ABS(Dataset!G10-Dataset!G11)) -> 39 | H25: =MAX(ABS(Dataset!B10-Dataset!B12),ABS(Dataset!C10-Dataset!C12),ABS(Dataset!D10-Dataset!D12),ABS(Dataset!E10-Dataset!E12),ABS(Dataset!F10-Dataset!F12),ABS(Dataset!G10-Dataset!G12)) -> 66 | I25: =MAX(ABS(Dataset!B10-Dataset!B13),ABS(Dataset!C10-Dataset!C13),ABS(Dataset!D10-Dataset!D13),ABS(Dataset!E10-Dataset!E13),ABS(Dataset!F10-Dataset!F13),ABS(Dataset!G10-Dataset!G13)) -> 63 | J25: =MAX(ABS(Dataset!B10-Dataset!B14),ABS(Dataset!C10-Dataset!C14),ABS(Dataset!D10-Dataset!D14),ABS(Dataset!E10-Dataset!E14),ABS(Dataset!F10-Dataset!F14),ABS(Dataset!G10-Dataset!G14)) -> 5 | K25: =MAX(ABS(Dataset!B10-Dataset!B15),ABS(Dataset!C10-Dataset!C15),ABS(Dataset!D10-Dataset!D15),ABS(Dataset!E10-Dataset!E15),ABS(Dataset!F10-Dataset!F15),ABS(Dataset!G10-Dataset!G15)) -> 6
A26: S6 | B26: =MAX(ABS(Dataset!B11-Dataset!B6),ABS(Dataset!C11-Dataset!C6),ABS(Dataset!D11-Dataset!D6),ABS(Dataset!E11-Dataset!E6),ABS(Dataset!F11-Dataset!F6),ABS(Dataset!G11-Dataset!G6)) -> 59 | C26: =MAX(ABS(Dataset!B11-Dataset!B7),ABS(Dataset!C11-Dataset!C7),ABS(Dataset!D11-Dataset!D7),ABS(Dataset!E11-Dataset!E7),ABS(Dataset!F11-Dataset!F7),ABS(Dataset!G11-Dataset!G7)) -> 34 | D26: =MAX(ABS(Dataset!B11-Dataset!B8),ABS(Dataset!C11-Dataset!C8),ABS(Dataset!D11-Dataset!D8),ABS(Dataset!E11-Dataset!E8),ABS(Dataset!F11-Dataset!F8),ABS(Dataset!G11-Dataset!G8)) -> 11 | E26: =MAX(ABS(Dataset!B11-Dataset!B9),ABS(Dataset!C11-Dataset!C9),ABS(Dataset!D11-Dataset!D9),ABS(Dataset!E11-Dataset!E9),ABS(Dataset!F11-Dataset!F9),ABS(Dataset!G11-Dataset!G9)) -> 18 | F26: =MAX(ABS(Dataset!B11-Dataset!B10),ABS(Dataset!C11-Dataset!C10),ABS(Dataset!D11-Dataset!D10),ABS(Dataset!E11-Dataset!E10),ABS(Dataset!F11-Dataset!F10),ABS(Dataset!G11-Dataset!G10)) -> 39 | G26: =MAX(ABS(Dataset!B11-Dataset!B11),ABS(Dataset!C11-Dataset!C11),ABS(Dataset!D11-Dataset!D11),ABS(Dataset!E11-Dataset!E11),ABS(Dataset!F11-Dataset!F11),ABS(Dataset!G11-Dataset!G11)) -> 0 | H26: =MAX(ABS(Dataset!B11-Dataset!B12),ABS(Dataset!C11-Dataset!C12),ABS(Dataset!D11-Dataset!D12),ABS(Dataset!E11-Dataset!E12),ABS(Dataset!F11-Dataset!F12),ABS(Dataset!G11-Dataset!G12)) -> 27 | I26: =MAX(ABS(Dataset!B11-Dataset!B13),ABS(Dataset!C11-Dataset!C13),ABS(Dataset!D11-Dataset!D13),ABS(Dataset!E11-Dataset!E13),ABS(Dataset!F11-Dataset!F13),ABS(Dataset!G11-Dataset!G13)) -> 24 | J26: =MAX(ABS(Dataset!B11-Dataset!B14),ABS(Dataset!C11-Dataset!C14),ABS(Dataset!D11-Dataset!D14),ABS(Dataset!E11-Dataset!E14),ABS(Dataset!F11-Dataset!F14),ABS(Dataset!G11-Dataset!G14)) -> 40 | K26: =MAX(ABS(Dataset!B11-Dataset!B15),ABS(Dataset!C11-Dataset!C15),ABS(Dataset!D11-Dataset!D15),ABS(Dataset!E11-Dataset!E15),ABS(Dataset!F11-Dataset!F15),ABS(Dataset!G11-Dataset!G15)) -> 44
A27: S7 | B27: =MAX(ABS(Dataset!B12-Dataset!B6),ABS(Dataset!C12-Dataset!C6),ABS(Dataset!D12-Dataset!D6),ABS(Dataset!E12-Dataset!E6),ABS(Dataset!F12-Dataset!F6),ABS(Dataset!G12-Dataset!G6)) -> 40 | C27: =MAX(ABS(Dataset!B12-Dataset!B7),ABS(Dataset!C12-Dataset!C7),ABS(Dataset!D12-Dataset!D7),ABS(Dataset!E12-Dataset!E7),ABS(Dataset!F12-Dataset!F7),ABS(Dataset!G12-Dataset!G7)) -> 21 | D27: =MAX(ABS(Dataset!B12-Dataset!B8),ABS(Dataset!C12-Dataset!C8),ABS(Dataset!D12-Dataset!D8),ABS(Dataset!E12-Dataset!E8),ABS(Dataset!F12-Dataset!F8),ABS(Dataset!G12-Dataset!G8)) -> 38 | E27: =MAX(ABS(Dataset!B12-Dataset!B9),ABS(Dataset!C12-Dataset!C9),ABS(Dataset!D12-Dataset!D9),ABS(Dataset!E12-Dataset!E9),ABS(Dataset!F12-Dataset!F9),ABS(Dataset!G12-Dataset!G9)) -> 16 | F27: =MAX(ABS(Dataset!B12-Dataset!B10),ABS(Dataset!C12-Dataset!C10),ABS(Dataset!D12-Dataset!D10),ABS(Dataset!E12-Dataset!E10),ABS(Dataset!F12-Dataset!F10),ABS(Dataset!G12-Dataset!G10)) -> 66 | G27: =MAX(ABS(Dataset!B12-Dataset!B11),ABS(Dataset!C12-Dataset!C11),ABS(Dataset!D12-Dataset!D11),ABS(Dataset!E12-Dataset!E11),ABS(Dataset!F12-Dataset!F11),ABS(Dataset!G12-Dataset!G11)) -> 27 | H27: =MAX(ABS(Dataset!B12-Dataset!B12),ABS(Dataset!C12-Dataset!C12),ABS(Dataset!D12-Dataset!D12),ABS(Dataset!E12-Dataset!E12),ABS(Dataset!F12-Dataset!F12),ABS(Dataset!G12-Dataset!G12)) -> 0 | I27: =MAX(ABS(Dataset!B12-Dataset!B13),ABS(Dataset!C12-Dataset!C13),ABS(Dataset!D12-Dataset!D13),ABS(Dataset!E12-Dataset!E13),ABS(Dataset!F12-Dataset!F13),ABS(Dataset!G12-Dataset!G13)) -> 9 | J27: =MAX(ABS(Dataset!B12-Dataset!B14),ABS(Dataset!C12-Dataset!C14),ABS(Dataset!D12-Dataset!D14),ABS(Dataset!E12-Dataset!E14),ABS(Dataset!F12-Dataset!F14),ABS(Dataset!G12-Dataset!G14)) -> 67 | K27: =MAX(ABS(Dataset!B12-Dataset!B15),ABS(Dataset!C12-Dataset!C15),ABS(Dataset!D12-Dataset!D15),ABS(Dataset!E12-Dataset!E15),ABS(Dataset!F12-Dataset!F15),ABS(Dataset!G12-Dataset!G15)) -> 71
A28: S8 | B28: =MAX(ABS(Dataset!B13-Dataset!B6),ABS(Dataset!C13-Dataset!C6),ABS(Dataset!D13-Dataset!D6),ABS(Dataset!E13-Dataset!E6),ABS(Dataset!F13-Dataset!F6),ABS(Dataset!G13-Dataset!G6)) -> 37 | C28: =MAX(ABS(Dataset!B13-Dataset!B7),ABS(Dataset!C13-Dataset!C7),ABS(Dataset!D13-Dataset!D7),ABS(Dataset!E13-Dataset!E7),ABS(Dataset!F13-Dataset!F7),ABS(Dataset!G13-Dataset!G7)) -> 18 | D28: =MAX(ABS(Dataset!B13-Dataset!B8),ABS(Dataset!C13-Dataset!C8),ABS(Dataset!D13-Dataset!D8),ABS(Dataset!E13-Dataset!E8),ABS(Dataset!F13-Dataset!F8),ABS(Dataset!G13-Dataset!G8)) -> 35 | E28: =MAX(ABS(Dataset!B13-Dataset!B9),ABS(Dataset!C13-Dataset!C9),ABS(Dataset!D13-Dataset!D9),ABS(Dataset!E13-Dataset!E9),ABS(Dataset!F13-Dataset!F9),ABS(Dataset!G13-Dataset!G9)) -> 13 | F28: =MAX(ABS(Dataset!B13-Dataset!B10),ABS(Dataset!C13-Dataset!C10),ABS(Dataset!D13-Dataset!D10),ABS(Dataset!E13-Dataset!E10),ABS(Dataset!F13-Dataset!F10),ABS(Dataset!G13-Dataset!G10)) -> 63 | G28: =MAX(ABS(Dataset!B13-Dataset!B11),ABS(Dataset!C13-Dataset!C11),ABS(Dataset!D13-Dataset!D11),ABS(Dataset!E13-Dataset!E11),ABS(Dataset!F13-Dataset!F11),ABS(Dataset!G13-Dataset!G11)) -> 24 | H28: =MAX(ABS(Dataset!B13-Dataset!B12),ABS(Dataset!C13-Dataset!C12),ABS(Dataset!D13-Dataset!D12),ABS(Dataset!E13-Dataset!E12),ABS(Dataset!F13-Dataset!F12),ABS(Dataset!G13-Dataset!G12)) -> 9 | I28: =MAX(ABS(Dataset!B13-Dataset!B13),ABS(Dataset!C13-Dataset!C13),ABS(Dataset!D13-Dataset!D13),ABS(Dataset!E13-Dataset!E13),ABS(Dataset!F13-Dataset!F13),ABS(Dataset!G13-Dataset!G13)) -> 0 | J28: =MAX(ABS(Dataset!B13-Dataset!B14),ABS(Dataset!C13-Dataset!C14),ABS(Dataset!D13-Dataset!D14),ABS(Dataset!E13-Dataset!E14),ABS(Dataset!F13-Dataset!F14),ABS(Dataset!G13-Dataset!G14)) -> 64 | K28: =MAX(ABS(Dataset!B13-Dataset!B15),ABS(Dataset!C13-Dataset!C15),ABS(Dataset!D13-Dataset!D15),ABS(Dataset!E13-Dataset!E15),ABS(Dataset!F13-Dataset!F15),ABS(Dataset!G13-Dataset!G15)) -> 68
A29: S9 | B29: =MAX(ABS(Dataset!B14-Dataset!B6),ABS(Dataset!C14-Dataset!C6),ABS(Dataset!D14-Dataset!D6),ABS(Dataset!E14-Dataset!E6),ABS(Dataset!F14-Dataset!F6),ABS(Dataset!G14-Dataset!G6)) -> 99 | C29: =MAX(ABS(Dataset!B14-Dataset!B7),ABS(Dataset!C14-Dataset!C7),ABS(Dataset!D14-Dataset!D7),ABS(Dataset!E14-Dataset!E7),ABS(Dataset!F14-Dataset!F7),ABS(Dataset!G14-Dataset!G7)) -> 74 | D29: =MAX(ABS(Dataset!B14-Dataset!B8),ABS(Dataset!C14-Dataset!C8),ABS(Dataset!D14-Dataset!D8),ABS(Dataset!E14-Dataset!E8),ABS(Dataset!F14-Dataset!F8),ABS(Dataset!G14-Dataset!G8)) -> 29 | E29: =MAX(ABS(Dataset!B14-Dataset!B9),ABS(Dataset!C14-Dataset!C9),ABS(Dataset!D14-Dataset!D9),ABS(Dataset!E14-Dataset!E9),ABS(Dataset!F14-Dataset!F9),ABS(Dataset!G14-Dataset!G9)) -> 58 | F29: =MAX(ABS(Dataset!B14-Dataset!B10),ABS(Dataset!C14-Dataset!C10),ABS(Dataset!D14-Dataset!D10),ABS(Dataset!E14-Dataset!E10),ABS(Dataset!F14-Dataset!F10),ABS(Dataset!G14-Dataset!G10)) -> 5 | G29: =MAX(ABS(Dataset!B14-Dataset!B11),ABS(Dataset!C14-Dataset!C11),ABS(Dataset!D14-Dataset!D11),ABS(Dataset!E14-Dataset!E11),ABS(Dataset!F14-Dataset!F11),ABS(Dataset!G14-Dataset!G11)) -> 40 | H29: =MAX(ABS(Dataset!B14-Dataset!B12),ABS(Dataset!C14-Dataset!C12),ABS(Dataset!D14-Dataset!D12),ABS(Dataset!E14-Dataset!E12),ABS(Dataset!F14-Dataset!F12),ABS(Dataset!G14-Dataset!G12)) -> 67 | I29: =MAX(ABS(Dataset!B14-Dataset!B13),ABS(Dataset!C14-Dataset!C13),ABS(Dataset!D14-Dataset!D13),ABS(Dataset!E14-Dataset!E13),ABS(Dataset!F14-Dataset!F13),ABS(Dataset!G14-Dataset!G13)) -> 64 | J29: =MAX(ABS(Dataset!B14-Dataset!B14),ABS(Dataset!C14-Dataset!C14),ABS(Dataset!D14-Dataset!D14),ABS(Dataset!E14-Dataset!E14),ABS(Dataset!F14-Dataset!F14),ABS(Dataset!G14-Dataset!G14)) -> 0 | K29: =MAX(ABS(Dataset!B14-Dataset!B15),ABS(Dataset!C14-Dataset!C15),ABS(Dataset!D14-Dataset!D15),ABS(Dataset!E14-Dataset!E15),ABS(Dataset!F14-Dataset!F15),ABS(Dataset!G14-Dataset!G15)) -> 4
A30: S10 | B30: =MAX(ABS(Dataset!B15-Dataset!B6),ABS(Dataset!C15-Dataset!C6),ABS(Dataset!D15-Dataset!D6),ABS(Dataset!E15-Dataset!E6),ABS(Dataset!F15-Dataset!F6),ABS(Dataset!G15-Dataset!G6)) -> 103 | C30: =MAX(ABS(Dataset!B15-Dataset!B7),ABS(Dataset!C15-Dataset!C7),ABS(Dataset!D15-Dataset!D7),ABS(Dataset!E15-Dataset!E7),ABS(Dataset!F15-Dataset!F7),ABS(Dataset!G15-Dataset!G7)) -> 78 | D30: =MAX(ABS(Dataset!B15-Dataset!B8),ABS(Dataset!C15-Dataset!C8),ABS(Dataset!D15-Dataset!D8),ABS(Dataset!E15-Dataset!E8),ABS(Dataset!F15-Dataset!F8),ABS(Dataset!G15-Dataset!G8)) -> 33 | E30: =MAX(ABS(Dataset!B15-Dataset!B9),ABS(Dataset!C15-Dataset!C9),ABS(Dataset!D15-Dataset!D9),ABS(Dataset!E15-Dataset!E9),ABS(Dataset!F15-Dataset!F9),ABS(Dataset!G15-Dataset!G9)) -> 62 | F30: =MAX(ABS(Dataset!B15-Dataset!B10),ABS(Dataset!C15-Dataset!C10),ABS(Dataset!D15-Dataset!D10),ABS(Dataset!E15-Dataset!E10),ABS(Dataset!F15-Dataset!F10),ABS(Dataset!G15-Dataset!G10)) -> 6 | G30: =MAX(ABS(Dataset!B15-Dataset!B11),ABS(Dataset!C15-Dataset!C11),ABS(Dataset!D15-Dataset!D11),ABS(Dataset!E15-Dataset!E11),ABS(Dataset!F15-Dataset!F11),ABS(Dataset!G15-Dataset!G11)) -> 44 | H30: =MAX(ABS(Dataset!B15-Dataset!B12),ABS(Dataset!C15-Dataset!C12),ABS(Dataset!D15-Dataset!D12),ABS(Dataset!E15-Dataset!E12),ABS(Dataset!F15-Dataset!F12),ABS(Dataset!G15-Dataset!G12)) -> 71 | I30: =MAX(ABS(Dataset!B15-Dataset!B13),ABS(Dataset!C15-Dataset!C13),ABS(Dataset!D15-Dataset!D13),ABS(Dataset!E15-Dataset!E13),ABS(Dataset!F15-Dataset!F13),ABS(Dataset!G15-Dataset!G13)) -> 68 | J30: =MAX(ABS(Dataset!B15-Dataset!B14),ABS(Dataset!C15-Dataset!C14),ABS(Dataset!D15-Dataset!D14),ABS(Dataset!E15-Dataset!E14),ABS(Dataset!F15-Dataset!F14),ABS(Dataset!G15-Dataset!G14)) -> 4 | K30: =MAX(ABS(Dataset!B15-Dataset!B15),ABS(Dataset!C15-Dataset!C15),ABS(Dataset!D15-Dataset!D15),ABS(Dataset!E15-Dataset!E15),ABS(Dataset!F15-Dataset!F15),ABS(Dataset!G15-Dataset!G15)) -> 0
A34: Canberra (None)
A35: Object | B35: S1 | C35: S2 | D35: S3 | E35: S4 | F35: S5 | G35: S6 | H35: S7 | I35: S8 | J35: S9 | K35: S10
A36: S1 | B36: =SUM(IF(ABS(Dataset!B6)+ABS(Dataset!B6)=0,0,ABS(Dataset!B6-Dataset!B6)/(ABS(Dataset!B6)+ABS(Dataset!B6))),IF(ABS(Dataset!C6)+ABS(Dataset!C6)=0,0,ABS(Dataset!C6-Dataset!C6)/(ABS(Dataset!C6)+ABS(Dataset!C6))),IF(ABS(Dataset!D6)+ABS(Dataset!D6)=0,0,ABS(Dataset!D6-Dataset!D6)/(ABS(Dataset!D6)+ABS(Dataset!D6))),IF(ABS(Dataset!E6)+ABS(Dataset!E6)=0,0,ABS(Dataset!E6-Dataset!E6)/(ABS(Dataset!E6)+ABS(Dataset!E6))),IF(ABS(Dataset!F6)+ABS(Dataset!F6)=0,0,ABS(Dataset!F6-Dataset!F6)/(ABS(Dataset!F6)+ABS(Dataset!F6))),IF(ABS(Dataset!G6)+ABS(Dataset!G6)=0,0,ABS(Dataset!G6-Dataset!G6)/(ABS(Dataset!G6)+ABS(Dataset!G6)))) -> 0 | C36: =SUM(IF(ABS(Dataset!B6)+ABS(Dataset!B7)=0,0,ABS(Dataset!B6-Dataset!B7)/(ABS(Dataset!B6)+ABS(Dataset!B7))),IF(ABS(Dataset!C6)+ABS(Dataset!C7)=0,0,ABS(Dataset!C6-Dataset!C7)/(ABS(Dataset!C6)+ABS(Dataset!C7))),IF(ABS(Dataset!D6)+ABS(Dataset!D7)=0,0,ABS(Dataset!D6-Dataset!D7)/(ABS(Dataset!D6)+ABS(Dataset!D7))),IF(ABS(Dataset!E6)+ABS(Dataset!E7)=0,0,ABS(Dataset!E6-Dataset!E7)/(ABS(Dataset!E6)+ABS(Dataset!E7))),IF(ABS(Dataset!F6)+ABS(Dataset!F7)=0,0,ABS(Dataset!F6-Dataset!F7)/(ABS(Dataset!F6)+ABS(Dataset!F7))),IF(ABS(Dataset!G6)+ABS(Dataset!G7)=0,0,ABS(Dataset!G6-Dataset!G7)/(ABS(Dataset!G6)+ABS(Dataset!G7)))) -> 0.54579992 | D36: =SUM(IF(ABS(Dataset!B6)+ABS(Dataset!B8)=0,0,ABS(Dataset!B6-Dataset!B8)/(ABS(Dataset!B6)+ABS(Dataset!B8))),IF(ABS(Dataset!C6)+ABS(Dataset!C8)=0,0,ABS(Dataset!C6-Dataset!C8)/(ABS(Dataset!C6)+ABS(Dataset!C8))),IF(ABS(Dataset!D6)+ABS(Dataset!D8)=0,0,ABS(Dataset!D6-Dataset!D8)/(ABS(Dataset!D6)+ABS(Dataset!D8))),IF(ABS(Dataset!E6)+ABS(Dataset!E8)=0,0,ABS(Dataset!E6-Dataset!E8)/(ABS(Dataset!E6)+ABS(Dataset!E8))),IF(ABS(Dataset!F6)+ABS(Dataset!F8)=0,0,ABS(Dataset!F6-Dataset!F8)/(ABS(Dataset!F6)+ABS(Dataset!F8))),IF(ABS(Dataset!G6)+ABS(Dataset!G8)=0,0,ABS(Dataset!G6-Dataset!G8)/(ABS(Dataset!G6)+ABS(Dataset!G8)))) -> 1.0373572 | E36: =SUM(IF(ABS(Dataset!B6)+ABS(Dataset!B9)=0,0,ABS(Dataset!B6-Dataset!B9)/(ABS(Dataset!B6)+ABS(Dataset!B9))),IF(ABS(Dataset!C6)+ABS(Dataset!C9)=0,0,ABS(Dataset!C6-Dataset!C9)/(ABS(Dataset!C6)+ABS(Dataset!C9))),IF(ABS(Dataset!D6)+ABS(Dataset!D9)=0,0,ABS(Dataset!D6-Dataset!D9)/(ABS(Dataset!D6)+ABS(Dataset!D9))),IF(ABS(Dataset!E6)+ABS(Dataset!E9)=0,0,ABS(Dataset!E6-Dataset!E9)/(ABS(Dataset!E6)+ABS(Dataset!E9))),IF(ABS(Dataset!F6)+ABS(Dataset!F9)=0,0,ABS(Dataset!F6-Dataset!F9)/(ABS(Dataset!F6)+ABS(Dataset!F9))),IF(ABS(Dataset!G6)+ABS(Dataset!G9)=0,0,ABS(Dataset!G6-Dataset!G9)/(ABS(Dataset!G6)+ABS(Dataset!G9)))) -> 0.56283496 | F36: =SUM(IF(ABS(Dataset!B6)+ABS(Dataset!B10)=0,0,ABS(Dataset!B6-Dataset!B10)/(ABS(Dataset!B6)+ABS(Dataset!B10))),IF(ABS(Dataset!C6)+ABS(Dataset!C10)=0,0,ABS(Dataset!C6-Dataset!C10)/(ABS(Dataset!C6)+ABS(Dataset!C10))),IF(ABS(Dataset!D6)+ABS(Dataset!D10)=0,0,ABS(Dataset!D6-Dataset!D10)/(ABS(Dataset!D6)+ABS(Dataset!D10))),IF(ABS(Dataset!E6)+ABS(Dataset!E10)=0,0,ABS(Dataset!E6-Dataset!E10)/(ABS(Dataset!E6)+ABS(Dataset!E10))),IF(ABS(Dataset!F6)+ABS(Dataset!F10)=0,0,ABS(Dataset!F6-Dataset!F10)/(ABS(Dataset!F6)+ABS(Dataset!F10))),IF(ABS(Dataset!G6)+ABS(Dataset!G10)=0,0,ABS(Dataset!G6-Dataset!G10)/(ABS(Dataset!G6)+ABS(Dataset!G10)))) -> 1.1520855 | G36: =SUM(IF(ABS(Dataset!B6)+ABS(Dataset!B11)=0,0,ABS(Dataset!B6-Dataset!B11)/(ABS(Dataset!B6)+ABS(Dataset!B11))),IF(ABS(Dataset!C6)+ABS(Dataset!C11)=0,0,ABS(Dataset!C6-Dataset!C11)/(ABS(Dataset!C6)+ABS(Dataset!C11))),IF(ABS(Dataset!D6)+ABS(Dataset!D11)=0,0,ABS(Dataset!D6-Dataset!D11)/(ABS(Dataset!D6)+ABS(Dataset!D11))),IF(ABS(Dataset!E6)+ABS(Dataset!E11)=0,0,ABS(Dataset!E6-Dataset!E11)/(ABS(Dataset!E6)+ABS(Dataset!E11))),IF(ABS(Dataset!F6)+ABS(Dataset!F11)=0,0,ABS(Dataset!F6-Dataset!F11)/(ABS(Dataset!F6)+ABS(Dataset!F11))),IF(ABS(Dataset!G6)+ABS(Dataset!G11)=0,0,ABS(Dataset!G6-Dataset!G11)/(ABS(Dataset!G6)+ABS(Dataset!G11)))) -> 0.68167905 | H36: =SUM(IF(ABS(Dataset!B6)+ABS(Dataset!B12)=0,0,ABS(Dataset!B6-Dataset!B12)/(ABS(Dataset!B6)+ABS(Dataset!B12))),IF(ABS(Dataset!C6)+ABS(Dataset!C12)=0,0,ABS(Dataset!C6-Dataset!C12)/(ABS(Dataset!C6)+ABS(Dataset!C12))),IF(ABS(Dataset!D6)+ABS(Dataset!D12)=0,0,ABS(Dataset!D6-Dataset!D12)/(ABS(Dataset!D6)+ABS(Dataset!D12))),IF(ABS(Dataset!E6)+ABS(Dataset!E12)=0,0,ABS(Dataset!E6-Dataset!E12)/(ABS(Dataset!E6)+ABS(Dataset!E12))),IF(ABS(Dataset!F6)+ABS(Dataset!F12)=0,0,ABS(Dataset!F6-Dataset!F12)/(ABS(Dataset!F6)+ABS(Dataset!F12))),IF(ABS(Dataset!G6)+ABS(Dataset!G12)=0,0,ABS(Dataset!G6-Dataset!G12)/(ABS(Dataset!G6)+ABS(Dataset!G12)))) -> 0.57429092 | I36: =SUM(IF(ABS(Dataset!B6)+ABS(Dataset!B13)=0,0,ABS(Dataset!B6-Dataset!B13)/(ABS(Dataset!B6)+ABS(Dataset!B13))),IF(ABS(Dataset!C6)+ABS(Dataset!C13)=0,0,ABS(Dataset!C6-Dataset!C13)/(ABS(Dataset!C6)+ABS(Dataset!C13))),IF(ABS(Dataset!D6)+ABS(Dataset!D13)=0,0,ABS(Dataset!D6-Dataset!D13)/(ABS(Dataset!D6)+ABS(Dataset!D13))),IF(ABS(Dataset!E6)+ABS(Dataset!E13)=0,0,ABS(Dataset!E6-Dataset!E13)/(ABS(Dataset!E6)+ABS(Dataset!E13))),IF(ABS(Dataset!F6)+ABS(Dataset!F13)=0,0,ABS(Dataset!F6-Dataset!F13)/(ABS(Dataset!F6)+ABS(Dataset!F13))),IF(ABS(Dataset!G6)+ABS(Dataset!G13)=0,0,ABS(Dataset!G6-Dataset!G13)/(ABS(Dataset!G6)+ABS(Dataset!G13)))) -> 0.62445561 | J36: =SUM(IF(ABS(Dataset!B6)+ABS(Dataset!B14)=0,0,ABS(Dataset!B6-Dataset!B14)/(ABS(Dataset!B6)+ABS(Dataset!B14))),IF(ABS(Dataset!C6)+ABS(Dataset!C14)=0,0,ABS(Dataset!C6-Dataset!C14)/(ABS(Dataset!C6)+ABS(Dataset!C14))),IF(ABS(Dataset!D6)+ABS(Dataset!D14)=0,0,ABS(Dataset!D6-Dataset!D14)/(ABS(Dataset!D6)+ABS(Dataset!D14))),IF(ABS(Dataset!E6)+ABS(Dataset!E14)=0,0,ABS(Dataset!E6-Dataset!E14)/(ABS(Dataset!E6)+ABS(Dataset!E14))),IF(ABS(Dataset!F6)+ABS(Dataset!F14)=0,0,ABS(Dataset!F6-Dataset!F14)/(ABS(Dataset!F6)+ABS(Dataset!F14))),IF(ABS(Dataset!G6)+ABS(Dataset!G14)=0,0,ABS(Dataset!G6-Dataset!G14)/(ABS(Dataset!G6)+ABS(Dataset!G14)))) -> 1.1237503 | K36: =SUM(IF(ABS(Dataset!B6)+ABS(Dataset!B15)=0,0,ABS(Dataset!B6-Dataset!B15)/(ABS(Dataset!B6)+ABS(Dataset!B15))),IF(ABS(Dataset!C6)+ABS(Dataset!C15)=0,0,ABS(Dataset!C6-Dataset!C15)/(ABS(Dataset!C6)+ABS(Dataset!C15))),IF(ABS(Dataset!D6)+ABS(Dataset!D15)=0,0,ABS(Dataset!D6-Dataset!D15)/(ABS(Dataset!D6)+ABS(Dataset!D15))),IF(ABS(Dataset!E6)+ABS(Dataset!E15)=0,0,ABS(Dataset!E6-Dataset!E15)/(ABS(Dataset!E6)+ABS(Dataset!E15))),IF(ABS(Dataset!F6)+ABS(Dataset!F15)=0,0,ABS(Dataset!F6-Dataset!F15)/(ABS(Dataset!F6)+ABS(Dataset!F15))),IF(ABS(Dataset!G6)+ABS(Dataset!G15)=0,0,ABS(Dataset!G6-Dataset!G15)/(ABS(Dataset!G6)+ABS(Dataset!G15)))) -> 1.1085058
